Traceback (most recent call last):
  File "/Users/KSIsleif/opt/anaconda3/lib/python3.9/site-packages/jupyter_cache/executors/utils.py", line 51, in single_nb_execution
    executenb(
  File "/Users/KSIsleif/opt/anaconda3/lib/python3.9/site-packages/nbclient/client.py", line 1204, in execute
    return NotebookClient(nb=nb, resources=resources, km=km, **kwargs).execute()
  File "/Users/KSIsleif/opt/anaconda3/lib/python3.9/site-packages/nbclient/util.py", line 84, in wrapped
    return just_run(coro(*args, **kwargs))
  File "/Users/KSIsleif/opt/anaconda3/lib/python3.9/site-packages/nbclient/util.py", line 62, in just_run
    return loop.run_until_complete(coro)
  File "/Users/KSIsleif/opt/anaconda3/lib/python3.9/asyncio/base_events.py", line 647, in run_until_complete
    return future.result()
  File "/Users/KSIsleif/opt/anaconda3/lib/python3.9/site-packages/nbclient/client.py", line 663, in async_execute
    await self.async_execute_cell(
  File "/Users/KSIsleif/opt/anaconda3/lib/python3.9/site-packages/nbclient/client.py", line 965, in async_execute_cell
    await self._check_raise_for_error(cell, cell_index, exec_reply)
  File "/Users/KSIsleif/opt/anaconda3/lib/python3.9/site-packages/nbclient/client.py", line 862, in _check_raise_for_error
    raise CellExecutionError.from_cell_and_msg(cell, exec_reply_content)
nbclient.exceptions.CellExecutionError: An error occurred while executing the following cell:
------------------
# Erstellen der DataFrames
data = pd.DataFrame({'x': x, 'y': y})

# Berechnung der Regressionskoeffizienten
x_mean = data['x'].mean()
y_mean = data['y'].mean()
xy_mean = (data['x'] * data['y']).mean()
x_squared_mean = (data['x']**2).mean()

b = (xy_mean - x_mean * y_mean) / (x_squared_mean - x_mean**2)
a = y_mean - b * x_mean

print("Regressionskoeffizient b:", m)
print("Regressionskoeffizient a:", n)

# Berechnung der GÃ¼tefunktion
data['b*x+a'] = m * data['x'] + n
data['y-(b*x+a)'] = data['y'] - data['b*x+a']
data['[y-(b*x+a)]^2'] = data['y-(b*x+a)']**2
sum_of_squared_residuals = data['[y-(b*x+a)]^2'].sum()


------------------

[0;31m---------------------------------------------------------------------------[0m
[0;31mNameError[0m                                 Traceback (most recent call last)
Cell [0;32mIn[2], line 13[0m
[1;32m     10[0m b [38;5;241m=[39m (xy_mean [38;5;241m-[39m x_mean [38;5;241m*[39m y_mean) [38;5;241m/[39m (x_squared_mean [38;5;241m-[39m x_mean[38;5;241m*[39m[38;5;241m*[39m[38;5;241m2[39m)
[1;32m     11[0m a [38;5;241m=[39m y_mean [38;5;241m-[39m b [38;5;241m*[39m x_mean
[0;32m---> 13[0m [38;5;28mprint[39m([38;5;124m"[39m[38;5;124mRegressionskoeffizient b:[39m[38;5;124m"[39m, [43mm[49m)
[1;32m     14[0m [38;5;28mprint[39m([38;5;124m"[39m[38;5;124mRegressionskoeffizient a:[39m[38;5;124m"[39m, n)
[1;32m     16[0m [38;5;66;03m# Berechnung der GÃ¼tefunktion[39;00m

[0;31mNameError[0m: name 'm' is not defined
NameError: name 'm' is not defined

