Traceback (most recent call last):
  File "/Users/KSIsleif/opt/anaconda3/lib/python3.9/site-packages/jupyter_cache/executors/utils.py", line 51, in single_nb_execution
    executenb(
  File "/Users/KSIsleif/opt/anaconda3/lib/python3.9/site-packages/nbclient/client.py", line 1112, in execute
    return NotebookClient(nb=nb, resources=resources, km=km, **kwargs).execute()
  File "/Users/KSIsleif/opt/anaconda3/lib/python3.9/site-packages/nbclient/util.py", line 74, in wrapped
    return just_run(coro(*args, **kwargs))
  File "/Users/KSIsleif/opt/anaconda3/lib/python3.9/site-packages/nbclient/util.py", line 53, in just_run
    return loop.run_until_complete(coro)
  File "/Users/KSIsleif/opt/anaconda3/lib/python3.9/asyncio/base_events.py", line 642, in run_until_complete
    return future.result()
  File "/Users/KSIsleif/opt/anaconda3/lib/python3.9/site-packages/nbclient/client.py", line 553, in async_execute
    await self.async_execute_cell(
  File "/Users/KSIsleif/opt/anaconda3/lib/python3.9/site-packages/nbclient/client.py", line 857, in async_execute_cell
    self._check_raise_for_error(cell, exec_reply)
  File "/Users/KSIsleif/opt/anaconda3/lib/python3.9/site-packages/nbclient/client.py", line 760, in _check_raise_for_error
    raise CellExecutionError.from_cell_and_msg(cell, exec_reply_content)
nbclient.exceptions.CellExecutionError: An error occurred while executing the following cell:
------------------
def fit_lin(x, b, a): # Fit Funktion f√ºr eine Gerade mit Steigung b
    return b*x + a

# Fit der Daten:
fit_out = optimization.curve_fit(fit_lin, x, t)

print('Die scipy-Fitparameter lauten:')
print('Die Steigung ist \t\t m = (%5.4f +- %5.4f) s/m' %(fit_out[0][0], np.sqrt(fit_out[1][0][0])))
print('Der Ordinatenabschnitt ist \t b = (%5.4f +- %5.4f) s' %(fit_out[0][1], np.sqrt(fit_out[1][1][1])))

plt.plot(x,t, 'o', label = 'Messwerte') # plot Messwerte
plt.plot(x,m*x+b, label = 'Lin. Reg.: y = %5.3f*x+%5.3f' %(m,b))  # plot Ausgleichsgerade mit m und b
plt.plot(x,fit_out[0][0]*x+fit_out[0][1], '--',label = 'Fit: y = %5.3f*x+%5.3f' %(fit_out[0][0],fit_out[0][1]))  # plot Fitfunktion mit b und a
plt.xlabel('Strecke x (m)')
plt.ylabel('Zeit t (s)')
plt.legend()
plt.show()
------------------

[0;31m---------------------------------------------------------------------------[0m
[0;31mNameError[0m                                 Traceback (most recent call last)
[0;32m/var/folders/6d/574ptfzx6v9_j7pylzkngrkm0000gp/T/ipykernel_11936/3303641914.py[0m in [0;36m<module>[0;34m[0m
[1;32m      3[0m [0;34m[0m[0m
[1;32m      4[0m [0;31m# Fit der Daten:[0m[0;34m[0m[0;34m[0m[0m
[0;32m----> 5[0;31m [0mfit_out[0m [0;34m=[0m [0moptimization[0m[0;34m.[0m[0mcurve_fit[0m[0;34m([0m[0mfit_lin[0m[0;34m,[0m [0mx[0m[0;34m,[0m [0mt[0m[0;34m)[0m[0;34m[0m[0;34m[0m[0m
[0m[1;32m      6[0m [0;34m[0m[0m
[1;32m      7[0m [0mprint[0m[0;34m([0m[0;34m'Die scipy-Fitparameter lauten:'[0m[0;34m)[0m[0;34m[0m[0;34m[0m[0m

[0;31mNameError[0m: name 'optimization' is not defined
NameError: name 'optimization' is not defined

