Traceback (most recent call last):
  File "/Users/KSIsleif/opt/anaconda3/lib/python3.9/site-packages/jupyter_cache/executors/utils.py", line 51, in single_nb_execution
    executenb(
  File "/Users/KSIsleif/opt/anaconda3/lib/python3.9/site-packages/nbclient/client.py", line 1204, in execute
    return NotebookClient(nb=nb, resources=resources, km=km, **kwargs).execute()
  File "/Users/KSIsleif/opt/anaconda3/lib/python3.9/site-packages/nbclient/util.py", line 84, in wrapped
    return just_run(coro(*args, **kwargs))
  File "/Users/KSIsleif/opt/anaconda3/lib/python3.9/site-packages/nbclient/util.py", line 62, in just_run
    return loop.run_until_complete(coro)
  File "/Users/KSIsleif/opt/anaconda3/lib/python3.9/asyncio/base_events.py", line 647, in run_until_complete
    return future.result()
  File "/Users/KSIsleif/opt/anaconda3/lib/python3.9/site-packages/nbclient/client.py", line 663, in async_execute
    await self.async_execute_cell(
  File "/Users/KSIsleif/opt/anaconda3/lib/python3.9/site-packages/nbclient/client.py", line 965, in async_execute_cell
    await self._check_raise_for_error(cell, cell_index, exec_reply)
  File "/Users/KSIsleif/opt/anaconda3/lib/python3.9/site-packages/nbclient/client.py", line 862, in _check_raise_for_error
    raise CellExecutionError.from_cell_and_msg(cell, exec_reply_content)
nbclient.exceptions.CellExecutionError: An error occurred while executing the following cell:
------------------
import numpy as np
import scipy.signal as signal
import matplotlib.pyplot as plt
# MatplotLib Settings:
plt.style.use('default') # Matplotlib Style w√§hlen
#plt.xkcd()
plt.rcParams['font.size'] = 10; # Schriftgr√∂√üe

# Transfer Funktion Tiefpass:
K = 1 # Verst√§rkungsfaktor
T = 1 # Zeit nach der 63% des Signals erreicht ist
num = np.array([K])
den = np.array([T , 1])
H = signal.TransferFunction(num , den)

y_impuls = ddf(t2,6.)
# Sprungantwort:
t, y = signal.step(H)

# Impulsantwort
t_imp, y_imp = signal.impulse(H)

# Plotting
fig, ax = plt.subplots(figsize=(9,4))
plt.subplot(1,2,1)
plt.axhline(y = 1.0, color='k', ls = '--', lw = 1)
plt.axhline(y = 0.95, color='k', ls = '--', lw = 1)
plt.axhline(y = 0.63, color='k', ls = '--', lw = 1)
plt.axvline(x = T, color='k', ls = '--', lw = 1)
plt.axvline(x = 3*T, color='k', ls = '--', lw = 1)
plt.plot(t2,y_step, color = 'tab:red', label = r'Sprunganregung $\sigma(t)$')
plt.plot(t, y, color='tab:blue', label = r'Sprungantwort $h(t)$')
plt.yticks([1.0, 0.95,0.63], labels = ['100%','95%', '63%'])
plt.xticks([0,T,3*T], labels = ['0',r'$\tau$',r'$3\tau$'])
plt.title("Sprungantwort eines Tiefpasses")
plt.xlabel("Zeit t")
plt.ylabel(r'$u_a(t)/u_0$')
plt.legend()

plt.subplot(1,2,2)
plt.plot(t2, y_impuls, color = 'tab:red', label = r'Impulsanregung $\delta(t)$')
plt.plot(t_imp, y_imp, color='tab:blue', label = r'Impulsantwort $g(t)$')
plt.yticks([1.0, 0.5,0.0], labels = ['100%','50%', '0%'])
plt.title("Impulsantwort eines Tiefpasses")
plt.xlabel("Zeit t")
plt.legend()
#plt.ylabel(r'$u_a(t)/u_0$')
plt.tight_layout
plt.show()
------------------

[0;31m---------------------------------------------------------------------------[0m
[0;31mNameError[0m                                 Traceback (most recent call last)
[0;32m/var/folders/6d/574ptfzx6v9_j7pylzkngrkm0000gp/T/ipykernel_36201/2976854337.py[0m in [0;36m<module>[0;34m[0m
[1;32m     14[0m [0mH[0m [0;34m=[0m [0msignal[0m[0;34m.[0m[0mTransferFunction[0m[0;34m([0m[0mnum[0m [0;34m,[0m [0mden[0m[0;34m)[0m[0;34m[0m[0;34m[0m[0m
[1;32m     15[0m [0;34m[0m[0m
[0;32m---> 16[0;31m [0my_impuls[0m [0;34m=[0m [0mddf[0m[0;34m([0m[0mt2[0m[0;34m,[0m[0;36m6.[0m[0;34m)[0m[0;34m[0m[0;34m[0m[0m
[0m[1;32m     17[0m [0;31m# Sprungantwort:[0m[0;34m[0m[0;34m[0m[0m
[1;32m     18[0m [0mt[0m[0;34m,[0m [0my[0m [0;34m=[0m [0msignal[0m[0;34m.[0m[0mstep[0m[0;34m([0m[0mH[0m[0;34m)[0m[0;34m[0m[0;34m[0m[0m

[0;31mNameError[0m: name 'ddf' is not defined
NameError: name 'ddf' is not defined

