Traceback (most recent call last):
  File "/Users/KSIsleif/opt/anaconda3/lib/python3.9/site-packages/jupyter_cache/executors/utils.py", line 58, in single_nb_execution
    executenb(
  File "/Users/KSIsleif/opt/anaconda3/lib/python3.9/site-packages/nbclient/client.py", line 1204, in execute
    return NotebookClient(nb=nb, resources=resources, km=km, **kwargs).execute()
  File "/Users/KSIsleif/opt/anaconda3/lib/python3.9/site-packages/nbclient/util.py", line 84, in wrapped
    return just_run(coro(*args, **kwargs))
  File "/Users/KSIsleif/opt/anaconda3/lib/python3.9/site-packages/nbclient/util.py", line 62, in just_run
    return loop.run_until_complete(coro)
  File "/Users/KSIsleif/opt/anaconda3/lib/python3.9/asyncio/base_events.py", line 647, in run_until_complete
    return future.result()
  File "/Users/KSIsleif/opt/anaconda3/lib/python3.9/site-packages/nbclient/client.py", line 663, in async_execute
    await self.async_execute_cell(
  File "/Users/KSIsleif/opt/anaconda3/lib/python3.9/site-packages/nbclient/client.py", line 965, in async_execute_cell
    await self._check_raise_for_error(cell, cell_index, exec_reply)
  File "/Users/KSIsleif/opt/anaconda3/lib/python3.9/site-packages/nbclient/client.py", line 862, in _check_raise_for_error
    raise CellExecutionError.from_cell_and_msg(cell, exec_reply_content)
nbclient.exceptions.CellExecutionError: An error occurred while executing the following cell:
------------------
print(f"Temperaturanstieg pro Jahr (von 1981 bis 2020): {model_lin1[0][0]:.3f}Â°C/Jahr")
print(f"Temperaturanstieg seit Beginn der Messung: {(y_model.iloc[-1]-y_model.iloc[0]):.3f}Â°C")
------------------

[0;31m---------------------------------------------------------------------------[0m
[0;31mNameError[0m                                 Traceback (most recent call last)
Cell [0;32mIn[20], line 2[0m
[1;32m      1[0m [38;5;28mprint[39m([38;5;124mf[39m[38;5;124m"[39m[38;5;124mTemperaturanstieg pro Jahr (von 1981 bis 2020): [39m[38;5;132;01m{[39;00mmodel_lin1[[38;5;241m0[39m][[38;5;241m0[39m][38;5;132;01m:[39;00m[38;5;124m.3f[39m[38;5;132;01m}[39;00m[38;5;124mÂ°C/Jahr[39m[38;5;124m"[39m)
[0;32m----> 2[0m [38;5;28mprint[39m([38;5;124mf[39m[38;5;124m"[39m[38;5;124mTemperaturanstieg seit Beginn der Messung: [39m[38;5;132;01m{[39;00m(y_model[38;5;241m.[39miloc[[38;5;241m-[39m[38;5;241m1[39m][38;5;241m-[39my_model[38;5;241m.[39miloc[[38;5;241m0[39m])[38;5;132;01m:[39;00m[38;5;124m.3f[39m[38;5;132;01m}[39;00m[38;5;124mÂ°C[39m[38;5;124m"[39m)

[0;31mNameError[0m: name 'y_model' is not defined
NameError: name 'y_model' is not defined

